{
  "CVE Code": "CVE-2010-3495",
  "Published": "2010-10-19T19:00:00",
  "Updated": "2024-08-07T03:11:44.310Z",
  "Description": "Race condition in ZEO/StorageServer.py in Zope Object Database (ZODB) before 3.10.0 allows remote attackers to cause a denial of service (daemon outage) by establishing and then immediately closing a TCP connection, leading to the accept function having an unexpected return value of None, an unexpected value of None for the address, or an ECONNABORTED, EAGAIN, or EWOULDBLOCK error, a related issue to CVE-2010-3492.",
  "ProblemTypes": [
    "n/a"
  ],
  "Affected": [
    {
      "vendor": "n/a",
      "product": "n/a",
      "versions": [
        "n/a"
      ]
    }
  ],
  "Reference": [
    "http://www.openwall.com/lists/oss-security/2010/09/11/2",
    "https://bugs.launchpad.net/zodb/+bug/135108",
    "http://pypi.python.org/pypi/ZODB3/3.10.0#id1",
    "http://www.openwall.com/lists/oss-security/2010/09/24/3",
    "http://www.openwall.com/lists/oss-security/2010/09/22/3",
    "http://bugs.python.org/issue6706",
    "http://www.openwall.com/lists/oss-security/2010/09/09/6",
    "http://lists.opensuse.org/opensuse-security-announce/2010-12/msg00006.html",
    "http://secunia.com/advisories/41755"
  ]
}