{
  "CVE Code": "CVE-2021-3737",
  "Published": "2022-03-04T00:00:00",
  "Updated": "2024-08-03T17:01:08.326Z",
  "Description": "A flaw was found in python. An improperly handled HTTP response in the HTTP client code of python may allow a remote attacker, who controls the HTTP server, to make the client script enter an infinite loop, consuming CPU time. The highest threat from this vulnerability is to system availability.",
  "ProblemTypes": [
    "CWE-835 - Loop with Unreachable Exit Condition ('Infinite Loop'), CWE-400 - Uncontrolled Resource Consumption"
  ],
  "Affected": [
    {
      "vendor": "n/a",
      "product": "python",
      "versions": [
        "Fixed in python v3.6.14, python v3.7.11, python v3.8.11, python v3.9.6, python v3.10.0b2"
      ]
    }
  ],
  "Reference": [
    "https://bugs.python.org/issue44022",
    "https://github.com/python/cpython/pull/25916",
    "https://bugzilla.redhat.com/show_bug.cgi?id=1995162",
    "https://github.com/python/cpython/pull/26503",
    "https://ubuntu.com/security/CVE-2021-3737",
    "https://www.oracle.com/security-alerts/cpujul2022.html",
    "https://python-security.readthedocs.io/vuln/urllib-100-continue-loop.html",
    "https://security.netapp.com/advisory/ntap-20220407-0009/",
    "https://lists.debian.org/debian-lts-announce/2023/05/msg00024.html",
    "https://lists.debian.org/debian-lts-announce/2023/06/msg00039.html"
  ]
}