{
  "CVE Code": "CVE-2020-35917",
  "Published": "2020-12-31T08:18:37",
  "Updated": "2024-08-04T17:16:13.190Z",
  "Description": "An issue was discovered in the pyo3 crate before 0.12.4 for Rust. There is a reference-counting error and use-after-free in From<Py<T>>.",
  "ProblemTypes": [
    "n/a"
  ],
  "Affected": [
    {
      "vendor": "n/a",
      "product": "n/a",
      "versions": [
        "n/a"
      ]
    }
  ],
  "Reference": [
    "https://rustsec.org/advisories/RUSTSEC-2020-0074.html"
  ]
}