{
  "CVE Code": "CVE-2021-47569",
  "Published": "2024-05-24T15:12:55.394Z",
  "Updated": "2025-05-04T07:13:50.733Z",
  "Description": "In the Linux kernel, the following vulnerability has been resolved:\n\nio_uring: fail cancellation for EXITING tasks\n\nWARNING: CPU: 1 PID: 20 at fs/io_uring.c:6269 io_try_cancel_userdata+0x3c5/0x640 fs/io_uring.c:6269\nCPU: 1 PID: 20 Comm: kworker/1:0 Not tainted 5.16.0-rc1-syzkaller #0\nWorkqueue: events io_fallback_req_func\nRIP: 0010:io_try_cancel_userdata+0x3c5/0x640 fs/io_uring.c:6269\nCall Trace:\n <TASK>\n io_req_task_link_timeout+0x6b/0x1e0 fs/io_uring.c:6886\n io_fallback_req_func+0xf9/0x1ae fs/io_uring.c:1334\n process_one_work+0x9b2/0x1690 kernel/workqueue.c:2298\n worker_thread+0x658/0x11f0 kernel/workqueue.c:2445\n kthread+0x405/0x4f0 kernel/kthread.c:327\n ret_from_fork+0x1f/0x30 arch/x86/entry/entry_64.S:295\n </TASK>\n\nWe need original task's context to do cancellations, so if it's dying\nand the callback is executed in a fallback mode, fail the cancellation\nattempt.",
  "ProblemTypes": [
    "N/A"
  ],
  "Affected": [
    {
      "vendor": "Linux",
      "product": "Linux",
      "versions": [
        "89b263f6d56e683ddcf7643140271ef6e36c72b9",
        "89b263f6d56e683ddcf7643140271ef6e36c72b9"
      ]
    },
    {
      "vendor": "Linux",
      "product": "Linux",
      "versions": [
        "5.15",
        "0",
        "5.15.6",
        "5.16"
      ]
    }
  ],
  "Reference": [
    "https://git.kernel.org/stable/c/3d2a1e68fd9904fdc1b02f2e7d40ca47df7ba39f",
    "https://git.kernel.org/stable/c/617a89484debcd4e7999796d693cf0b77d2519de"
  ]
}